Workbook

Sheet Company Overview
A1: GREGGS PLC
A2: Company Overview | FY2024-FY2025
A3: COMPANY INFORMATION
A4: Item | B4: Information
A5: Company | B5: Greggs plc
A6: Stock ticker | B6: GRG
A7: Industry | B7: Bakery / Food retail
A8: Headquarters | B8: Newcastle upon Tyne, UK
A9: Main operations | B9: UK bakery and ready-made food retailer, responsible for manufacturing and distribution operations.
A10: Financial years analysed | B10: FY2024 and FY2025
A11: Source annual report | B11: Annual Report and Accounts 2025
A12: External auditor | B12: RSM UK Audit LLP
A13: BUSINESS OVERVIEW
A14: Greggs plc is a UK-based bakery and ready-made food retailer that specialises in freshly prepared products, including sandwiches, sausage rolls, pastries and hot drinks. The company operated 2,739 retail stores across the UK as of the 2025 financial year-end, including company-managed and franchised shops, supported by its vertically integrated supply chain, which encompasses manufacturing and distribution. Its financial performance is influenced by sales volumes, food and labour costs, production and property expenses, as well as store expansion and investment in manufacturing and logistics infrastructure.
A15: OBJECTIVES OF THE ANALYSIS
A16: 1. Assess changes in Greggs' financial performance and financial position between FY2024 and FY2025.
A17: 2. Evaluate cash generation and capital investment, and examine the relationship between reported profit and operating cash flow.
A18: 3. Identify financial reporting risks and propose appropriate audit procedures.
A19: Sources: Greggs plc, Annual Report and Accounts 2025.

Sheet Financial Statements
A1: GREGGS PLC
A2: Selected Historical Financial Data | £m
A3: INCOME STATEMENT
A4: £ million | B4: FY2024 | C4: FY2025
A5: Revenue | B5: 2014.4 | C5: 2151.2
A6: Cost of sales | B6: 770.8 | C6: 829.1
A7: Gross profit | B7: 1243.6 | C7: 1322.1
A8: Distribution & selling costs | B8: 950.1 | C8: 1036.3
A9: Administrative expenses | B9: 97.9 | C9: 102.1
A10: Other income | B10: 13.8 | C10: 0
A11: Operating profit | B11: 209.4 | C11: 183.7
A12: Finance income | B12: 8.1 | C12: 1.8
A13: Finance expense | B13: 13.6 | C13: 18.1
A14: Profit before tax | B14: 203.9 | C14: 167.4
A15: Income tax | B15: 50.5 | C15: 45.2
A16: Net profit | B16: 153.4 | C16: 122.2
A17: BALANCE SHEET
A18: £ million | B18: FY2024 | C18: FY2025
A19: Property, plant & equipment | B19: 664.7 | C19: 832.1
A20: Right-of-use assets | B20: 387.2 | C20: 413
A21: Inventories | B21: 55.2 | C21: 55.7
A22: Trade & other receivables | B22: 62.4 | C22: 69.4
A23: Cash & cash equivalents | B23: 125.3 | C23: 70.8
A24: Total assets | B24: 1319.7 | C24: 1484
A25: Trade & other payables | B25: 243.9 | C25: 272.8
A26: Current lease liabilities | B26: 53.8 | C26: 62.5
A27: Non-current lease liabilities | B27: 361.3 | C27: 387.3
A28: Total liabilities | B28: 749.2 | C28: 858.8
A29: Net assets | B29: 570.5 | C29: 625.2
A30: CASH FLOW STATEMENT
A31: £ million | B31: FY2024 | C31: FY2025
A32: Cash generated from operations | B32: 352.6 | C32: 383.7
A33: Net cash from operating activities | B33: 318.6 | C33: 337
A34: Purchase of PPE / capex | B34: 230 | C34: 263.3
A35: Purchase of intangible assets | B35: 10.9 | C35: 22.1
A36: Dividends paid | B36: 106.8 | C36: 70.3
A37: Closing cash | B37: 125.3 | C37: 70.8
A38: OPERATING CASH FLOW RECONCILIATION - SUPPORTING DATA
A39: £ million | B39: FY2024 | C39: FY2025
A40: Amortisation | B40: 4.2 | C40: 4.7
...

Sheet Ratio Analysis
A1: GREGGS PLC
A2: Ratio & Trend Analysis | FY2024-FY2025
A3: PROFITABILITY & CASH GENERATION
A4: Financial ratio | B4: FY2024 | C4: FY2025
A5: Revenue growth | B5: N/A | C5: =('Financial Statements'!C5/'Financial Statements'!B5)-1 -> 0.067911041
A6: Gross profit margin | B6: ='Financial Statements'!B7/'Financial Statements'!B5 -> 0.61735504 | C6: ='Financial Statements'!C7/'Financial Statements'!C5 -> 0.61458721
A7: Operating profit margin | B7: ='Financial Statements'!B11/'Financial Statements'!B5 -> 0.10395155 | C7: ='Financial Statements'!C11/'Financial Statements'!C5 -> 0.085394199
A8: Net profit margin | B8: ='Financial Statements'!B16/'Financial Statements'!B5 -> 0.076151708 | C8: ='Financial Statements'!C16/'Financial Statements'!C5 -> 0.056805504
A9: Operating cash conversion | B9: ='Financial Statements'!B33/'Financial Statements'!B11 -> 1.52149 | C9: ='Financial Statements'!C33/'Financial Statements'!C11 -> 1.8345128
A10: YEAR-ON-YEAR COST & PROFIT MOVEMENTS
A11: Financial item | B11: Change (£m) | C11: Change (%)
A12: Revenue | B12: ='Financial Statements'!C5-'Financial Statements'!B5 -> 136.8 | C12: =B12/'Financial Statements'!B5 -> 0.067911041
A13: Cost of sales | B13: ='Financial Statements'!C6-'Financial Statements'!B6 -> 58.3 | C13: =B13/'Financial Statements'!B6 -> 0.075635703
A14: Distribution & selling costs | B14: ='Financial Statements'!C8-'Financial Statements'!B8 -> 86.2 | C14: =B14/'Financial Statements'!B8 -> 0.090727292
A15: Administrative expenses | B15: ='Financial Statements'!C9-'Financial Statements'!B9 -> 4.2 | C15: =B15/'Financial Statements'!B9 -> 0.042900919
A16: Other income | B16: ='Financial Statements'!C10-'Financial Statements'!B10 -> -13.8 | C16: =B16/'Financial Statements'!B10 -> -1
A17: Operating profit | B17: ='Financial Statements'!C11-'Financial Statements'!B11 -> -25.7 | C17: =B17/'Financial Statements'!B11 -> -0.12273161
A18: UNDERLYING OPERATING PERFORMANCE
A19: Financial item | B19: FY2024 | C19: FY2025
A20: Statutory operating profit (£m) | B20: ='Financial Statements'!B11 -> 209.4 | C20: ='Financial Statements'!C11 -> 183.7
A21: Exceptional impact (£m) | B21: 14.1 | C21: -3.8
A22: Underlying operating profit (£m) | B22: =B20-B21 -> 195.3 | C22: =C20-C21 -> 187.5
A23: Underlying operating margin | B23: =B22/'Financial Statements'!B5 -> 0.096951946 | C23: =C22/'Financial Statements'!C5 -> 0.087160655
A24: Underlying operating profit growth | B24: N/A | C24: =(C22-B22)/B22 -> -0.039938556
A25: Source: Greggs plc, Annual Report and Accounts 2025, pp128, 132 and 148.

Sheet Earnings Quality
A1: GREGGS PLC
A2: Earnings Quality Analysis | FY2024-FY2025
A3: CASH GENERATION & CAPITAL INVESTMENT
A4: Financial item (£m) | B4: FY2024 | C4: FY2025
A5: Net profit | B5: ='Financial Statements'!B16 -> 153.4 | C5: ='Financial Statements'!C16 -> 122.2
A6: Net cash from operating activities | B6: ='Financial Statements'!B33 -> 318.6 | C6: ='Financial Statements'!C33 -> 337
A7: Purchase of PPE / CAPEX | B7: ='Financial Statements'!B34 -> 230 | C7: ='Financial Statements'!C34 -> 263.3
A8: Purchase of intangible assets | B8: ='Financial Statements'!B35 -> 10.9 | C8: ='Financial Statements'!C35 -> 22.1
A9: Total capital investment | B9: =B7+B8 -> 240.9 | C9: =C7+C8 -> 285.4
A10: Cash flow after capital investment | B10: =B6-B9 -> 77.7 | C10: =C6-C9 -> 51.6
A11: PROFIT-TO-CASH RECONCILIATION
A12: Financial item (£m) | B12: FY2024 | C12: FY2025
A13: Net profit | B13: ='Financial Statements'!B16 -> 153.4 | C13: ='Financial Statements'!C16 -> 122.2
A14: Depreciation & amortisation | B14: ='Financial Statements'!B40+'Financial Statements'!B41+'Financial Statements'!B42 -> 140 | C14: ='Financial Statements'!C40+'Financial Statements'!C41+'Financial Statements'!C42 -> 160.6
A15: Impairment adjustments | B15: ='Financial Statements'!B46+'Financial Statements'!B47 -> 5 | C15: ='Financial Statements'!C46+'Financial Statements'!C47 -> 6.9
A16: Net working capital adjustments | B16: ='Financial Statements'!B43+'Financial Statements'!B44+'Financial Statements'!B45 -> 10.4 | C16: ='Financial Statements'!C43+'Financial Statements'!C44+'Financial Statements'!C45 -> 23.8
A17: Income tax & net finance expense adjustments | B17: ='Financial Statements'!B15+'Financial Statements'!B13-'Financial Statements'!B12 -> 56 | C17: ='Financial Statements'!C15+'Financial Statements'!C13-'Financial Statements'!C12 -> 61.5
A18: Other reconciling adjustments (excluding impairment) | B18: ='Financial Statements'!B48 -> -12.2 | C18: ='Financial Statements'!C48 -> 8.7
A19: Cash generated from operations | B19: =SUM(B13:B18) -> 352.6 | C19: =SUM(C13:C18) -> 383.7
A20: Tax and net interest cash flows | B20: ='Financial Statements'!B49 -> -34 | C20: ='Financial Statements'!C49 -> -46.7
A21: Net cash from operating activities | B21: =SUM(B19:B20) -> 318.6 | C21: =SUM(C19:C20) -> 337
A22: WORKING CAPITAL ANALYSIS
A23: Financial item (£m) | B23: FY2024 | C23: FY2025
A24: Increase in inventories | B24: ='Financial Statements'!B43 -> -6.4 | C24: ='Financial Statements'!C43 -> -0.4
A25: Increase in receivables | B25: ='Financial Statements'!B44 -> -8.1 | C25: ='Financial Statements'!C44 -> -7.4
A26: Increase in payables | B26: ='Financial Statements'!B45 -> 24.9 | C26: ='Financial Statements'!C45 -> 31.6
A27: Net working capital adjustments | B27: =SUM(B24:B26) -> 10.4 | C27: =SUM(C24:C26) -> 23.8
A28: Year-on-year change in working capital adjustments | B28: N/A | C28: =C27-B27 -> 13.4
A29: EARNINGS QUALITY ASSESSMENT
A30: 1. Profitability: Net profit fell from £153.4m to £122.2m despite revenue growth. However, exceptional items affected the comparison, so this decline doesn’t entirely reflect weaker normal trading.
A31: 2. Cash generation: net operating cash flow increased from £318.6m to £337.0m, despite the lower profit, supported partly by larger adjustments for non-cash expenses and higher payables. The cash benefit from higher payables may not recur, thus the increase in net operating cash flow may not also represent improved earnings quality.
A32: 3. Capital investment: Cash remaining after capital investment fell from £77.7m to £51.6m, as the increase in investment exceeded the rise in operating cash flow. These amounts are before lease principal payments and dividends.
A33: Source: Greggs plc, Annual Report and Accounts 2025, pp128 and 132-133.

Sheet Audit Risk
A1: GREGGS PLC
A2: Audit Risk Analysis | FY2025
A3: AUDIT OVERVIEW AND MATERIALITY
A4: Financial item (£m unless otherwise stated) | B4: FY2024 | C4: FY2025 | D4: Audit relevance
A5: Group overall materiality | B5: 9.25 | C5: 8.01 | D5: Threshold set by RSM to assess whether misstatements, individually or together, could reasonably influence the decisions of users of the financial statements.
A6: Group performance materiality | B6: 6.94 | C6: 5.6 | D6: Lower threshold used in planning and performing the audit to reduce the risk of multiple uncorrected and undetected misstatements together exceeding overall materiality.
A7: Reporting threshold to Audit Committee | B7: 0.462 | C7: 0.4 | D7: Threshold above which RSM reports identified misstatements to Greggs' Audit Committee. Smaller misstatements may also be reported based on their nature.
A8: Property, plant & equipment | B8: ='Financial Statements'!B19 -> 664.7 | C8: ='Financial Statements'!C19 -> 832.1 | D8: Greggs' significant PPE balance could be overstated if depreciation or impairment losses are understated.
A9: Right-of-use assets | B9: ='Financial Statements'!B20 -> 387.2 | C9: ='Financial Statements'!C20 -> 413 | D9: Greggs' significant right-of-use asset balance could be overstated if impairment losses on leased shops are understated.
A10: Impairment adjustments | B10: ='Earnings Quality'!B15 -> 5 | C10: ='Earnings Quality'!C15 -> 6.9 | D10: Impairment losses depend on management's forecasts of shop sales, costs and resulting cash flows. Overly optimistic assumptions could understate impairment losses and overstate assets and profit.
A11: AUDIT REPORT CONTEXT
A12: External auditor | B12: RSM UK Audit LLP
A13: Audit opinion | B13: Unmodified audit opinion
A14: Key audit matter | B14: Recoverability of shop-based assets
A15: AUDIT RISKS & PROPOSED PROCEDURES
A16: Risk area | B16: Significance | C16: Potential misstatement | D16: Proposed audit procedures
A17: Recoverability of shop-based assets | B17: Greggs holds significant balances of PPE and right-of-use assets. Assessing their recoverability depends on estimates of future cash flows and profitability, which rely on assumptions made by management, introducing uncertainty. | C17: Overly optimistic forecasts could result in insufficient impairment losses being recognised, overstating the recorded value of shop-based assets and reported profit. | D17: 1. Compare previous forecasts with actual shop performance to assess forecasting accuracy. 2. Compare forecasts of costs and sales as well as assumed discount rates with recent shop performance and market data to assess their credibility. 3. Check the impairment model's input values and formulas to identify errors in the calculation of recoverable amounts. 4. Reduce forecast sales and increase forecast costs in the model to assess whether worse shop performance would require additional impairment losses.
A18: Revenue recognition and cut-off | B18: Greggs reported £2,151.2m in revenue during FY2025. Given this high volume of sales transactions, accurate recording and recognition in the correct accounting period are important. | C18: Revenue and profit could be understated or overstated if sales are recorded in the wrong accounting period, particularly significant around year end. | D18: 1. Examine a sample of sales immediately before and after year end to check that they were recorded in the correct period. 2. Compare sales in the accounting records with till and payment records to check accuracy. 3. Compare accounting entries for sales to other businesses with invoices, delivery records and sales terms to check that revenue was recognised in the correct accounting period.
A19: Capital expenditure classification | B19: Greggs spent £263.3m purchasing PPE in FY2025. This high level of spending makes it important to distinguish costs that should be recorded as assets from those that should be recognised as operating expenses. | C19: Recording routine operating costs as assets could overstate non-current assets and profit. Conversely, recording qualifying capital expenditure as an expense could understate both. | D19: 1. Inspect invoices and supporting records for selected asset additions and operating expenses to establish what the spending relates to. 2. Check whether these costs meet the criteria for capitalisation and were correctly recorded as assets or expenses. 3. Check that depreciation started when the assets became available for use.
A20: AUDIT RISK CONCLUSION
A21: Recoverability of shop-based assets is the main focus of this audit analysis and was the key audit matter reported by RSM. Assessing these assets relies on forecasts of future shop performance, which involve uncertainty. This report also considers revenue recognition and capital expenditure classification due to the large volume of sales and scale of investment. Errors could misstate assets and profit, misclassify expenses or place revenue in the wrong accounting period. The proposed procedures focus on checking forecast assumptions, testing revenue recording and assessing whether expenditure should be capitalised or expensed.
A22: Greggs plc, Annual Report and Accounts 2025, pp121-124 and 128-133
